[2024-10-28 14:12:52,548: INFO/MainProcess] beat: Starting...
 
 -------------- celery@debian-hpelite v5.4.0 (opalescent)
--- ***** ----- 
-- ******* ---- Linux-5.10.0-33-amd64-x86_64-with-glibc2.31 2024-10-28 14:12:52
- *** --- * --- 
- ** ---------- [config]
- ** ---------- .> app:         conciergerie:0x7f9cd26cc580
- ** ---------- .> transport:   redis://localhost:6379//
- ** ---------- .> results:     redis://localhost:6379/
- *** --- * --- .> concurrency: 4 (prefork)
-- ******* ---- .> task events: OFF (enable -E to monitor tasks in this worker)
--- ***** ----- 
 -------------- [queues]
                .> celery           exchange=celery(direct) key=celery
                

[tasks]


[2024-10-28 14:12:52,998: INFO/MainProcess] Connected to redis://localhost:6379//
[2024-10-28 14:12:53,002: INFO/MainProcess] mingle: searching for neighbors
[2024-10-28 14:12:54,011: INFO/MainProcess] mingle: all alone
[2024-10-28 14:12:54,025: INFO/MainProcess] celery@debian-hpelite ready.
[2024-10-29 06:51:14,637: INFO/MainProcess] Scheduler: Sending due task update-resa-status (services_menage.tasks.cron_update_reservation_status)
[2024-10-29 06:51:14,653: INFO/MainProcess] Scheduler: Sending due task create-events-daily (services_menage.tasks.service_checkin_task)
[2024-10-29 06:51:14,654: ERROR/MainProcess] Received unregistered task of type 'services_menage.tasks.cron_update_reservation_status'.
The message has been ignored and discarded.

Did you remember to import the module containing this task?
Or maybe you're using relative imports?

Please see
https://docs.celeryq.dev/en/latest/internals/protocol.html
for more information.

The full contents of the message body was:
b'[[], {}, {"callbacks": null, "errbacks": null, "chain": null, "chord": null}]' (77b)

The full contents of the message headers:
{'lang': 'py', 'task': 'services_menage.tasks.cron_update_reservation_status', 'id': 'e7a00055-b0a9-4a68-be71-b4136f3529ca', 'shadow': None, 'eta': None, 'expires': None, 'group': None, 'group_index': None, 'retries': 0, 'timelimit': [None, None], 'root_id': 'e7a00055-b0a9-4a68-be71-b4136f3529ca', 'parent_id': None, 'argsrepr': '()', 'kwargsrepr': '{}', 'origin': 'gen491575@debian-hpelite', 'ignore_result': False, 'replaced_task_nesting': 0, 'stamped_headers': None, 'stamps': {}}

The delivery info for this task is:
{'exchange': '', 'routing_key': 'celery'}
Traceback (most recent call last):
  File "/home/django/Depots/www/Back-end/Django/envCeleryConciergerie/lib/python3.9/site-packages/celery/worker/consumer/consumer.py", line 659, in on_task_received
    strategy = strategies[type_]
KeyError: 'services_menage.tasks.cron_update_reservation_status'
[2024-10-29 06:51:34,185: ERROR/MainProcess] Received unregistered task of type 'services_menage.tasks.cron_update_reservation_status'.
The message has been ignored and discarded.

Did you remember to import the module containing this task?
Or maybe you're using relative imports?

Please see
https://docs.celeryq.dev/en/latest/internals/protocol.html
for more information.

The full contents of the message body was:
b'[[], {}, {"callbacks": null, "errbacks": null, "chain": null, "chord": null}]' (77b)

The full contents of the message headers:
{'lang': 'py', 'task': 'services_menage.tasks.cron_update_reservation_status', 'id': 'e8def136-bd27-4752-b888-2ed56fc950e1', 'shadow': None, 'eta': None, 'expires': None, 'group': None, 'group_index': None, 'retries': 0, 'timelimit': [None, None], 'root_id': 'e8def136-bd27-4752-b888-2ed56fc950e1', 'parent_id': None, 'argsrepr': '()', 'kwargsrepr': '{}', 'origin': 'gen491786@debian-hpelite', 'ignore_result': False, 'replaced_task_nesting': 0, 'stamped_headers': None, 'stamps': {}}

The delivery info for this task is:
{'exchange': '', 'routing_key': 'celery'}
Traceback (most recent call last):
  File "/home/django/Depots/www/Back-end/Django/envCeleryConciergerie/lib/python3.9/site-packages/celery/worker/consumer/consumer.py", line 659, in on_task_received
    strategy = strategies[type_]
KeyError: 'services_menage.tasks.cron_update_reservation_status'
